2023-12-21 14:58:21,289 ERROR scheduler Exception in Enqueue Events for Site erp.gabby.com
Traceback (most recent call last):
  File "env/lib/python3.10/site-packages/pymysql/connections.py", line 736, in _read_bytes
    data = self._rfile.read(num_bytes)
  File "/usr/lib/python3.10/socket.py", line 705, in readinto
    return self._sock.recv_into(b)
ConnectionResetError: [Errno 104] Connection reset by peer

During handling of the above exception, another exception occurred:

Traceback (most recent call last):
  File "apps/frappe/frappe/utils/scheduler.py", line 75, in enqueue_events_for_site
    if is_scheduler_inactive():
  File "apps/frappe/frappe/utils/scheduler.py", line 114, in is_scheduler_inactive
    if is_scheduler_disabled(verbose=verbose):
  File "apps/frappe/frappe/utils/scheduler.py", line 127, in is_scheduler_disabled
    frappe.db.get_single_value("System Settings", "enable_scheduler")
  File "apps/frappe/frappe/database/database.py", line 786, in get_single_value
    ).run()
  File "apps/frappe/frappe/query_builder/utils.py", line 87, in execute_query
    result = frappe.db.sql(query, params, *args, **kwargs)  # nosemgrep
  File "apps/frappe/frappe/database/database.py", line 201, in sql
    self.connect()
  File "apps/frappe/frappe/database/database.py", line 115, in connect
    self._conn = self.get_connection()
  File "apps/frappe/frappe/database/mariadb/database.py", line 98, in get_connection
    conn = self._get_connection()
  File "apps/frappe/frappe/database/mariadb/database.py", line 104, in _get_connection
    return self.create_connection()
  File "apps/frappe/frappe/database/mariadb/database.py", line 107, in create_connection
    return pymysql.connect(**self.get_connection_settings())
  File "env/lib/python3.10/site-packages/pymysql/connections.py", line 352, in __init__
    self.connect()
  File "env/lib/python3.10/site-packages/pymysql/connections.py", line 636, in connect
    self._request_authentication()
  File "env/lib/python3.10/site-packages/pymysql/connections.py", line 911, in _request_authentication
    auth_packet = self._read_packet()
  File "env/lib/python3.10/site-packages/pymysql/connections.py", line 696, in _read_packet
    packet_header = self._read_bytes(4)
  File "env/lib/python3.10/site-packages/pymysql/connections.py", line 742, in _read_bytes
    raise err.OperationalError(
pymysql.err.OperationalError: (2013, 'Lost connection to MySQL server during query ([Errno 104] Connection reset by peer)')

2023-12-21 15:47:54,021 ERROR scheduler Skipped queueing frappe.email.queue.flush because it was found in queue for erp.gabby.com
2023-12-21 16:08:18,095 ERROR scheduler Exception in Enqueue Events for Site erp.gabby.com
Traceback (most recent call last):
  File "env/lib/python3.10/site-packages/pymysql/connections.py", line 736, in _read_bytes
    data = self._rfile.read(num_bytes)
  File "/usr/lib/python3.10/socket.py", line 705, in readinto
    return self._sock.recv_into(b)
ConnectionResetError: [Errno 104] Connection reset by peer

During handling of the above exception, another exception occurred:

Traceback (most recent call last):
  File "apps/frappe/frappe/utils/scheduler.py", line 75, in enqueue_events_for_site
    if is_scheduler_inactive():
  File "apps/frappe/frappe/utils/scheduler.py", line 114, in is_scheduler_inactive
    if is_scheduler_disabled(verbose=verbose):
  File "apps/frappe/frappe/utils/scheduler.py", line 127, in is_scheduler_disabled
    frappe.db.get_single_value("System Settings", "enable_scheduler")
  File "apps/frappe/frappe/database/database.py", line 786, in get_single_value
    ).run()
  File "apps/frappe/frappe/query_builder/utils.py", line 87, in execute_query
    result = frappe.db.sql(query, params, *args, **kwargs)  # nosemgrep
  File "apps/frappe/frappe/database/database.py", line 201, in sql
    self.connect()
  File "apps/frappe/frappe/database/database.py", line 115, in connect
    self._conn = self.get_connection()
  File "apps/frappe/frappe/database/mariadb/database.py", line 98, in get_connection
    conn = self._get_connection()
  File "apps/frappe/frappe/database/mariadb/database.py", line 104, in _get_connection
    return self.create_connection()
  File "apps/frappe/frappe/database/mariadb/database.py", line 107, in create_connection
    return pymysql.connect(**self.get_connection_settings())
  File "env/lib/python3.10/site-packages/pymysql/connections.py", line 352, in __init__
    self.connect()
  File "env/lib/python3.10/site-packages/pymysql/connections.py", line 636, in connect
    self._request_authentication()
  File "env/lib/python3.10/site-packages/pymysql/connections.py", line 911, in _request_authentication
    auth_packet = self._read_packet()
  File "env/lib/python3.10/site-packages/pymysql/connections.py", line 696, in _read_packet
    packet_header = self._read_bytes(4)
  File "env/lib/python3.10/site-packages/pymysql/connections.py", line 742, in _read_bytes
    raise err.OperationalError(
pymysql.err.OperationalError: (2013, 'Lost connection to MySQL server during query ([Errno 104] Connection reset by peer)')

2024-01-18 13:50:54,889 ERROR scheduler Exception in Enqueue Events for Site erp.gabby.com
Traceback (most recent call last):
  File "env/lib/python3.10/site-packages/pymysql/connections.py", line 736, in _read_bytes
    data = self._rfile.read(num_bytes)
  File "/usr/lib/python3.10/socket.py", line 705, in readinto
    return self._sock.recv_into(b)
ConnectionResetError: [Errno 104] Connection reset by peer

During handling of the above exception, another exception occurred:

Traceback (most recent call last):
  File "apps/frappe/frappe/utils/scheduler.py", line 75, in enqueue_events_for_site
    if is_scheduler_inactive():
  File "apps/frappe/frappe/utils/scheduler.py", line 114, in is_scheduler_inactive
    if is_scheduler_disabled(verbose=verbose):
  File "apps/frappe/frappe/utils/scheduler.py", line 127, in is_scheduler_disabled
    frappe.db.get_single_value("System Settings", "enable_scheduler")
  File "apps/frappe/frappe/database/database.py", line 786, in get_single_value
    ).run()
  File "apps/frappe/frappe/query_builder/utils.py", line 87, in execute_query
    result = frappe.db.sql(query, params, *args, **kwargs)  # nosemgrep
  File "apps/frappe/frappe/database/database.py", line 201, in sql
    self.connect()
  File "apps/frappe/frappe/database/database.py", line 115, in connect
    self._conn = self.get_connection()
  File "apps/frappe/frappe/database/mariadb/database.py", line 98, in get_connection
    conn = self._get_connection()
  File "apps/frappe/frappe/database/mariadb/database.py", line 104, in _get_connection
    return self.create_connection()
  File "apps/frappe/frappe/database/mariadb/database.py", line 107, in create_connection
    return pymysql.connect(**self.get_connection_settings())
  File "env/lib/python3.10/site-packages/pymysql/connections.py", line 352, in __init__
    self.connect()
  File "env/lib/python3.10/site-packages/pymysql/connections.py", line 636, in connect
    self._request_authentication()
  File "env/lib/python3.10/site-packages/pymysql/connections.py", line 911, in _request_authentication
    auth_packet = self._read_packet()
  File "env/lib/python3.10/site-packages/pymysql/connections.py", line 696, in _read_packet
    packet_header = self._read_bytes(4)
  File "env/lib/python3.10/site-packages/pymysql/connections.py", line 742, in _read_bytes
    raise err.OperationalError(
pymysql.err.OperationalError: (2013, 'Lost connection to MySQL server during query ([Errno 104] Connection reset by peer)')

2024-01-19 10:37:53,259 ERROR scheduler Skipped queueing erpnext.utilities.doctype.video.video.update_youtube_data because it was found in queue for erp.gabby.com
2024-01-19 13:39:14,126 ERROR scheduler Skipped queueing hrms.hr.doctype.shift_type.shift_type.process_auto_attendance_for_all_shifts because it was found in queue for erp.gabby.com
2024-01-19 13:40:56,424 ERROR scheduler Skipped queueing hrms.hr.doctype.shift_type.shift_type.process_auto_attendance_for_all_shifts because it was found in queue for erp.gabby.com
2024-01-19 13:42:11,196 ERROR scheduler Skipped queueing hrms.hr.doctype.shift_type.shift_type.process_auto_attendance_for_all_shifts because it was found in queue for erp.gabby.com
2024-01-19 13:43:35,363 ERROR scheduler Skipped queueing hrms.hr.doctype.shift_type.shift_type.process_auto_attendance_for_all_shifts because it was found in queue for erp.gabby.com
2024-01-19 14:27:50,298 ERROR scheduler Skipped queueing frappe.email.doctype.email_account.email_account.pull because it was found in queue for erp.gabby.com
2024-01-22 13:34:57,800 ERROR scheduler Skipped queueing erpnext.manufacturing.doctype.bom_update_log.bom_update_log.resume_bom_cost_update_jobs because it was found in queue for erp.gabby.com
2024-01-22 15:00:32,294 ERROR scheduler Skipped queueing erpnext.crm.doctype.social_media_post.social_media_post.process_scheduled_social_media_posts because it was found in queue for erp.gabby.com
2024-01-24 13:05:15,865 ERROR scheduler Exception in Enqueue Events for Site erp.gabby.com
Traceback (most recent call last):
  File "env/lib/python3.10/site-packages/pymysql/connections.py", line 616, in connect
    sock = socket.create_connection(
  File "/usr/lib/python3.10/socket.py", line 845, in create_connection
    raise err
  File "/usr/lib/python3.10/socket.py", line 833, in create_connection
    sock.connect(sa)
ConnectionResetError: [Errno 104] Connection reset by peer

During handling of the above exception, another exception occurred:

Traceback (most recent call last):
  File "apps/frappe/frappe/utils/scheduler.py", line 75, in enqueue_events_for_site
    if is_scheduler_inactive():
  File "apps/frappe/frappe/utils/scheduler.py", line 114, in is_scheduler_inactive
    if is_scheduler_disabled(verbose=verbose):
  File "apps/frappe/frappe/utils/scheduler.py", line 127, in is_scheduler_disabled
    frappe.db.get_single_value("System Settings", "enable_scheduler")
  File "apps/frappe/frappe/database/database.py", line 786, in get_single_value
    ).run()
  File "apps/frappe/frappe/query_builder/utils.py", line 87, in execute_query
    result = frappe.db.sql(query, params, *args, **kwargs)  # nosemgrep
  File "apps/frappe/frappe/database/database.py", line 201, in sql
    self.connect()
  File "apps/frappe/frappe/database/database.py", line 115, in connect
    self._conn = self.get_connection()
  File "apps/frappe/frappe/database/mariadb/database.py", line 98, in get_connection
    conn = self._get_connection()
  File "apps/frappe/frappe/database/mariadb/database.py", line 104, in _get_connection
    return self.create_connection()
  File "apps/frappe/frappe/database/mariadb/database.py", line 107, in create_connection
    return pymysql.connect(**self.get_connection_settings())
  File "env/lib/python3.10/site-packages/pymysql/connections.py", line 352, in __init__
    self.connect()
  File "env/lib/python3.10/site-packages/pymysql/connections.py", line 668, in connect
    raise exc
pymysql.err.OperationalError: (2003, "Can't connect to MySQL server on '127.0.0.1' ([Errno 104] Connection reset by peer)")

2024-01-24 14:57:27,700 ERROR scheduler Exception in Enqueue Events for Site erp.gabby.com
Traceback (most recent call last):
  File "env/lib/python3.10/site-packages/pymysql/connections.py", line 736, in _read_bytes
    data = self._rfile.read(num_bytes)
  File "/usr/lib/python3.10/socket.py", line 705, in readinto
    return self._sock.recv_into(b)
ConnectionResetError: [Errno 104] Connection reset by peer

During handling of the above exception, another exception occurred:

Traceback (most recent call last):
  File "apps/frappe/frappe/utils/scheduler.py", line 75, in enqueue_events_for_site
    if is_scheduler_inactive():
  File "apps/frappe/frappe/utils/scheduler.py", line 114, in is_scheduler_inactive
    if is_scheduler_disabled(verbose=verbose):
  File "apps/frappe/frappe/utils/scheduler.py", line 127, in is_scheduler_disabled
    frappe.db.get_single_value("System Settings", "enable_scheduler")
  File "apps/frappe/frappe/database/database.py", line 786, in get_single_value
    ).run()
  File "apps/frappe/frappe/query_builder/utils.py", line 87, in execute_query
    result = frappe.db.sql(query, params, *args, **kwargs)  # nosemgrep
  File "apps/frappe/frappe/database/database.py", line 201, in sql
    self.connect()
  File "apps/frappe/frappe/database/database.py", line 115, in connect
    self._conn = self.get_connection()
  File "apps/frappe/frappe/database/mariadb/database.py", line 98, in get_connection
    conn = self._get_connection()
  File "apps/frappe/frappe/database/mariadb/database.py", line 104, in _get_connection
    return self.create_connection()
  File "apps/frappe/frappe/database/mariadb/database.py", line 107, in create_connection
    return pymysql.connect(**self.get_connection_settings())
  File "env/lib/python3.10/site-packages/pymysql/connections.py", line 352, in __init__
    self.connect()
  File "env/lib/python3.10/site-packages/pymysql/connections.py", line 636, in connect
    self._request_authentication()
  File "env/lib/python3.10/site-packages/pymysql/connections.py", line 911, in _request_authentication
    auth_packet = self._read_packet()
  File "env/lib/python3.10/site-packages/pymysql/connections.py", line 696, in _read_packet
    packet_header = self._read_bytes(4)
  File "env/lib/python3.10/site-packages/pymysql/connections.py", line 742, in _read_bytes
    raise err.OperationalError(
pymysql.err.OperationalError: (2013, 'Lost connection to MySQL server during query ([Errno 104] Connection reset by peer)')

2024-01-24 15:29:40,328 ERROR scheduler Exception in Enqueue Events for Site erp.gabby.com
Traceback (most recent call last):
  File "env/lib/python3.10/site-packages/pymysql/connections.py", line 616, in connect
    sock = socket.create_connection(
  File "/usr/lib/python3.10/socket.py", line 845, in create_connection
    raise err
  File "/usr/lib/python3.10/socket.py", line 833, in create_connection
    sock.connect(sa)
ConnectionResetError: [Errno 104] Connection reset by peer

During handling of the above exception, another exception occurred:

Traceback (most recent call last):
  File "apps/frappe/frappe/utils/scheduler.py", line 75, in enqueue_events_for_site
    if is_scheduler_inactive():
  File "apps/frappe/frappe/utils/scheduler.py", line 114, in is_scheduler_inactive
    if is_scheduler_disabled(verbose=verbose):
  File "apps/frappe/frappe/utils/scheduler.py", line 127, in is_scheduler_disabled
    frappe.db.get_single_value("System Settings", "enable_scheduler")
  File "apps/frappe/frappe/database/database.py", line 786, in get_single_value
    ).run()
  File "apps/frappe/frappe/query_builder/utils.py", line 87, in execute_query
    result = frappe.db.sql(query, params, *args, **kwargs)  # nosemgrep
  File "apps/frappe/frappe/database/database.py", line 201, in sql
    self.connect()
  File "apps/frappe/frappe/database/database.py", line 115, in connect
    self._conn = self.get_connection()
  File "apps/frappe/frappe/database/mariadb/database.py", line 98, in get_connection
    conn = self._get_connection()
  File "apps/frappe/frappe/database/mariadb/database.py", line 104, in _get_connection
    return self.create_connection()
  File "apps/frappe/frappe/database/mariadb/database.py", line 107, in create_connection
    return pymysql.connect(**self.get_connection_settings())
  File "env/lib/python3.10/site-packages/pymysql/connections.py", line 352, in __init__
    self.connect()
  File "env/lib/python3.10/site-packages/pymysql/connections.py", line 668, in connect
    raise exc
pymysql.err.OperationalError: (2003, "Can't connect to MySQL server on '127.0.0.1' ([Errno 104] Connection reset by peer)")

2024-01-24 16:16:10,943 ERROR scheduler Exception in Enqueue Events for Site erp.gabby.com
Traceback (most recent call last):
  File "env/lib/python3.10/site-packages/pymysql/connections.py", line 736, in _read_bytes
    data = self._rfile.read(num_bytes)
  File "/usr/lib/python3.10/socket.py", line 705, in readinto
    return self._sock.recv_into(b)
ConnectionResetError: [Errno 104] Connection reset by peer

During handling of the above exception, another exception occurred:

Traceback (most recent call last):
  File "apps/frappe/frappe/utils/scheduler.py", line 75, in enqueue_events_for_site
    if is_scheduler_inactive():
  File "apps/frappe/frappe/utils/scheduler.py", line 114, in is_scheduler_inactive
    if is_scheduler_disabled(verbose=verbose):
  File "apps/frappe/frappe/utils/scheduler.py", line 127, in is_scheduler_disabled
    frappe.db.get_single_value("System Settings", "enable_scheduler")
  File "apps/frappe/frappe/database/database.py", line 786, in get_single_value
    ).run()
  File "apps/frappe/frappe/query_builder/utils.py", line 87, in execute_query
    result = frappe.db.sql(query, params, *args, **kwargs)  # nosemgrep
  File "apps/frappe/frappe/database/database.py", line 201, in sql
    self.connect()
  File "apps/frappe/frappe/database/database.py", line 115, in connect
    self._conn = self.get_connection()
  File "apps/frappe/frappe/database/mariadb/database.py", line 98, in get_connection
    conn = self._get_connection()
  File "apps/frappe/frappe/database/mariadb/database.py", line 104, in _get_connection
    return self.create_connection()
  File "apps/frappe/frappe/database/mariadb/database.py", line 107, in create_connection
    return pymysql.connect(**self.get_connection_settings())
  File "env/lib/python3.10/site-packages/pymysql/connections.py", line 352, in __init__
    self.connect()
  File "env/lib/python3.10/site-packages/pymysql/connections.py", line 636, in connect
    self._request_authentication()
  File "env/lib/python3.10/site-packages/pymysql/connections.py", line 911, in _request_authentication
    auth_packet = self._read_packet()
  File "env/lib/python3.10/site-packages/pymysql/connections.py", line 696, in _read_packet
    packet_header = self._read_bytes(4)
  File "env/lib/python3.10/site-packages/pymysql/connections.py", line 742, in _read_bytes
    raise err.OperationalError(
pymysql.err.OperationalError: (2013, 'Lost connection to MySQL server during query ([Errno 104] Connection reset by peer)')

2024-01-25 14:26:02,229 ERROR scheduler Exception in Enqueue Events for Site erp.gabby.com
Traceback (most recent call last):
  File "env/lib/python3.10/site-packages/pymysql/connections.py", line 736, in _read_bytes
    data = self._rfile.read(num_bytes)
  File "/usr/lib/python3.10/socket.py", line 705, in readinto
    return self._sock.recv_into(b)
ConnectionResetError: [Errno 104] Connection reset by peer

During handling of the above exception, another exception occurred:

Traceback (most recent call last):
  File "apps/frappe/frappe/utils/scheduler.py", line 75, in enqueue_events_for_site
    if is_scheduler_inactive():
  File "apps/frappe/frappe/utils/scheduler.py", line 114, in is_scheduler_inactive
    if is_scheduler_disabled(verbose=verbose):
  File "apps/frappe/frappe/utils/scheduler.py", line 127, in is_scheduler_disabled
    frappe.db.get_single_value("System Settings", "enable_scheduler")
  File "apps/frappe/frappe/database/database.py", line 786, in get_single_value
    ).run()
  File "apps/frappe/frappe/query_builder/utils.py", line 87, in execute_query
    result = frappe.db.sql(query, params, *args, **kwargs)  # nosemgrep
  File "apps/frappe/frappe/database/database.py", line 201, in sql
    self.connect()
  File "apps/frappe/frappe/database/database.py", line 115, in connect
    self._conn = self.get_connection()
  File "apps/frappe/frappe/database/mariadb/database.py", line 98, in get_connection
    conn = self._get_connection()
  File "apps/frappe/frappe/database/mariadb/database.py", line 104, in _get_connection
    return self.create_connection()
  File "apps/frappe/frappe/database/mariadb/database.py", line 107, in create_connection
    return pymysql.connect(**self.get_connection_settings())
  File "env/lib/python3.10/site-packages/pymysql/connections.py", line 352, in __init__
    self.connect()
  File "env/lib/python3.10/site-packages/pymysql/connections.py", line 636, in connect
    self._request_authentication()
  File "env/lib/python3.10/site-packages/pymysql/connections.py", line 911, in _request_authentication
    auth_packet = self._read_packet()
  File "env/lib/python3.10/site-packages/pymysql/connections.py", line 696, in _read_packet
    packet_header = self._read_bytes(4)
  File "env/lib/python3.10/site-packages/pymysql/connections.py", line 742, in _read_bytes
    raise err.OperationalError(
pymysql.err.OperationalError: (2013, 'Lost connection to MySQL server during query ([Errno 104] Connection reset by peer)')

2024-01-29 09:41:04,475 ERROR scheduler Exception in Enqueue Events for Site erp.gabby.com
Traceback (most recent call last):
  File "apps/frappe/frappe/utils/scheduler.py", line 78, in enqueue_events_for_site
    enqueue_events(site=site)
  File "apps/frappe/frappe/utils/scheduler.py", line 100, in enqueue_events
    frappe.get_doc("Scheduled Job Type", job_type.name).enqueue()
  File "apps/frappe/frappe/__init__.py", line 1205, in get_doc
    doc = frappe.model.document.get_doc(*args, **kwargs)
  File "apps/frappe/frappe/model/document.py", line 75, in get_doc
    return controller(*args, **kwargs)
  File "apps/frappe/frappe/model/document.py", line 107, in __init__
    self.load_from_db()
  File "apps/frappe/frappe/model/document.py", line 146, in load_from_db
    d = frappe.db.get_value(
  File "apps/frappe/frappe/database/database.py", line 509, in get_value
    result = self.get_values(
  File "apps/frappe/frappe/database/database.py", line 606, in get_values
    out = self._get_values_from_table(
  File "apps/frappe/frappe/database/database.py", line 835, in _get_values_from_table
    return query.run(as_dict=as_dict, debug=debug, update=update, run=run, pluck=pluck)
  File "apps/frappe/frappe/query_builder/utils.py", line 87, in execute_query
    result = frappe.db.sql(query, params, *args, **kwargs)  # nosemgrep
  File "apps/frappe/frappe/database/database.py", line 220, in sql
    self._cursor.execute(query, values)
  File "env/lib/python3.10/site-packages/pymysql/cursors.py", line 158, in execute
    result = self._query(query)
  File "env/lib/python3.10/site-packages/pymysql/cursors.py", line 325, in _query
    conn.query(q)
  File "env/lib/python3.10/site-packages/pymysql/connections.py", line 549, in query
    self._affected_rows = self._read_query_result(unbuffered=unbuffered)
  File "env/lib/python3.10/site-packages/pymysql/connections.py", line 779, in _read_query_result
    result.read()
  File "env/lib/python3.10/site-packages/pymysql/connections.py", line 1157, in read
    first_packet = self.connection._read_packet()
  File "env/lib/python3.10/site-packages/pymysql/connections.py", line 696, in _read_packet
    packet_header = self._read_bytes(4)
  File "env/lib/python3.10/site-packages/pymysql/connections.py", line 752, in _read_bytes
    raise err.OperationalError(
pymysql.err.OperationalError: (2013, 'Lost connection to MySQL server during query')

2024-01-29 09:42:37,146 ERROR scheduler Exception in Enqueue Events for Site erp.gabby.com
Traceback (most recent call last):
  File "env/lib/python3.10/site-packages/pymysql/connections.py", line 616, in connect
    sock = socket.create_connection(
  File "/usr/lib/python3.10/socket.py", line 845, in create_connection
    raise err
  File "/usr/lib/python3.10/socket.py", line 833, in create_connection
    sock.connect(sa)
ConnectionRefusedError: [Errno 111] Connection refused

During handling of the above exception, another exception occurred:

Traceback (most recent call last):
  File "apps/frappe/frappe/utils/scheduler.py", line 75, in enqueue_events_for_site
    if is_scheduler_inactive():
  File "apps/frappe/frappe/utils/scheduler.py", line 114, in is_scheduler_inactive
    if is_scheduler_disabled(verbose=verbose):
  File "apps/frappe/frappe/utils/scheduler.py", line 127, in is_scheduler_disabled
    frappe.db.get_single_value("System Settings", "enable_scheduler")
  File "apps/frappe/frappe/database/database.py", line 786, in get_single_value
    ).run()
  File "apps/frappe/frappe/query_builder/utils.py", line 87, in execute_query
    result = frappe.db.sql(query, params, *args, **kwargs)  # nosemgrep
  File "apps/frappe/frappe/database/database.py", line 201, in sql
    self.connect()
  File "apps/frappe/frappe/database/database.py", line 115, in connect
    self._conn = self.get_connection()
  File "apps/frappe/frappe/database/mariadb/database.py", line 98, in get_connection
    conn = self._get_connection()
  File "apps/frappe/frappe/database/mariadb/database.py", line 104, in _get_connection
    return self.create_connection()
  File "apps/frappe/frappe/database/mariadb/database.py", line 107, in create_connection
    return pymysql.connect(**self.get_connection_settings())
  File "env/lib/python3.10/site-packages/pymysql/connections.py", line 352, in __init__
    self.connect()
  File "env/lib/python3.10/site-packages/pymysql/connections.py", line 668, in connect
    raise exc
pymysql.err.OperationalError: (2003, "Can't connect to MySQL server on '127.0.0.1' ([Errno 111] Connection refused)")

2024-01-29 09:43:37,937 ERROR scheduler Exception in Enqueue Events for Site erp.gabby.com
Traceback (most recent call last):
  File "env/lib/python3.10/site-packages/pymysql/connections.py", line 616, in connect
    sock = socket.create_connection(
  File "/usr/lib/python3.10/socket.py", line 845, in create_connection
    raise err
  File "/usr/lib/python3.10/socket.py", line 833, in create_connection
    sock.connect(sa)
ConnectionRefusedError: [Errno 111] Connection refused

During handling of the above exception, another exception occurred:

Traceback (most recent call last):
  File "apps/frappe/frappe/utils/scheduler.py", line 75, in enqueue_events_for_site
    if is_scheduler_inactive():
  File "apps/frappe/frappe/utils/scheduler.py", line 114, in is_scheduler_inactive
    if is_scheduler_disabled(verbose=verbose):
  File "apps/frappe/frappe/utils/scheduler.py", line 127, in is_scheduler_disabled
    frappe.db.get_single_value("System Settings", "enable_scheduler")
  File "apps/frappe/frappe/database/database.py", line 786, in get_single_value
    ).run()
  File "apps/frappe/frappe/query_builder/utils.py", line 87, in execute_query
    result = frappe.db.sql(query, params, *args, **kwargs)  # nosemgrep
  File "apps/frappe/frappe/database/database.py", line 201, in sql
    self.connect()
  File "apps/frappe/frappe/database/database.py", line 115, in connect
    self._conn = self.get_connection()
  File "apps/frappe/frappe/database/mariadb/database.py", line 98, in get_connection
    conn = self._get_connection()
  File "apps/frappe/frappe/database/mariadb/database.py", line 104, in _get_connection
    return self.create_connection()
  File "apps/frappe/frappe/database/mariadb/database.py", line 107, in create_connection
    return pymysql.connect(**self.get_connection_settings())
  File "env/lib/python3.10/site-packages/pymysql/connections.py", line 352, in __init__
    self.connect()
  File "env/lib/python3.10/site-packages/pymysql/connections.py", line 668, in connect
    raise exc
pymysql.err.OperationalError: (2003, "Can't connect to MySQL server on '127.0.0.1' ([Errno 111] Connection refused)")

2024-01-29 09:44:38,308 ERROR scheduler Exception in Enqueue Events for Site erp.gabby.com
Traceback (most recent call last):
  File "env/lib/python3.10/site-packages/pymysql/connections.py", line 616, in connect
    sock = socket.create_connection(
  File "/usr/lib/python3.10/socket.py", line 845, in create_connection
    raise err
  File "/usr/lib/python3.10/socket.py", line 833, in create_connection
    sock.connect(sa)
ConnectionRefusedError: [Errno 111] Connection refused

During handling of the above exception, another exception occurred:

Traceback (most recent call last):
  File "apps/frappe/frappe/utils/scheduler.py", line 75, in enqueue_events_for_site
    if is_scheduler_inactive():
  File "apps/frappe/frappe/utils/scheduler.py", line 114, in is_scheduler_inactive
    if is_scheduler_disabled(verbose=verbose):
  File "apps/frappe/frappe/utils/scheduler.py", line 127, in is_scheduler_disabled
    frappe.db.get_single_value("System Settings", "enable_scheduler")
  File "apps/frappe/frappe/database/database.py", line 786, in get_single_value
    ).run()
  File "apps/frappe/frappe/query_builder/utils.py", line 87, in execute_query
    result = frappe.db.sql(query, params, *args, **kwargs)  # nosemgrep
  File "apps/frappe/frappe/database/database.py", line 201, in sql
    self.connect()
  File "apps/frappe/frappe/database/database.py", line 115, in connect
    self._conn = self.get_connection()
  File "apps/frappe/frappe/database/mariadb/database.py", line 98, in get_connection
    conn = self._get_connection()
  File "apps/frappe/frappe/database/mariadb/database.py", line 104, in _get_connection
    return self.create_connection()
  File "apps/frappe/frappe/database/mariadb/database.py", line 107, in create_connection
    return pymysql.connect(**self.get_connection_settings())
  File "env/lib/python3.10/site-packages/pymysql/connections.py", line 352, in __init__
    self.connect()
  File "env/lib/python3.10/site-packages/pymysql/connections.py", line 668, in connect
    raise exc
pymysql.err.OperationalError: (2003, "Can't connect to MySQL server on '127.0.0.1' ([Errno 111] Connection refused)")

2024-01-29 09:45:39,945 ERROR scheduler Exception in Enqueue Events for Site erp.gabby.com
Traceback (most recent call last):
  File "env/lib/python3.10/site-packages/pymysql/connections.py", line 616, in connect
    sock = socket.create_connection(
  File "/usr/lib/python3.10/socket.py", line 845, in create_connection
    raise err
  File "/usr/lib/python3.10/socket.py", line 833, in create_connection
    sock.connect(sa)
ConnectionRefusedError: [Errno 111] Connection refused

During handling of the above exception, another exception occurred:

Traceback (most recent call last):
  File "apps/frappe/frappe/utils/scheduler.py", line 75, in enqueue_events_for_site
    if is_scheduler_inactive():
  File "apps/frappe/frappe/utils/scheduler.py", line 114, in is_scheduler_inactive
    if is_scheduler_disabled(verbose=verbose):
  File "apps/frappe/frappe/utils/scheduler.py", line 127, in is_scheduler_disabled
    frappe.db.get_single_value("System Settings", "enable_scheduler")
  File "apps/frappe/frappe/database/database.py", line 786, in get_single_value
    ).run()
  File "apps/frappe/frappe/query_builder/utils.py", line 87, in execute_query
    result = frappe.db.sql(query, params, *args, **kwargs)  # nosemgrep
  File "apps/frappe/frappe/database/database.py", line 201, in sql
    self.connect()
  File "apps/frappe/frappe/database/database.py", line 115, in connect
    self._conn = self.get_connection()
  File "apps/frappe/frappe/database/mariadb/database.py", line 98, in get_connection
    conn = self._get_connection()
  File "apps/frappe/frappe/database/mariadb/database.py", line 104, in _get_connection
    return self.create_connection()
  File "apps/frappe/frappe/database/mariadb/database.py", line 107, in create_connection
    return pymysql.connect(**self.get_connection_settings())
  File "env/lib/python3.10/site-packages/pymysql/connections.py", line 352, in __init__
    self.connect()
  File "env/lib/python3.10/site-packages/pymysql/connections.py", line 668, in connect
    raise exc
pymysql.err.OperationalError: (2003, "Can't connect to MySQL server on '127.0.0.1' ([Errno 111] Connection refused)")

2024-01-29 09:46:42,969 ERROR scheduler Exception in Enqueue Events for Site erp.gabby.com
Traceback (most recent call last):
  File "env/lib/python3.10/site-packages/pymysql/connections.py", line 616, in connect
    sock = socket.create_connection(
  File "/usr/lib/python3.10/socket.py", line 845, in create_connection
    raise err
  File "/usr/lib/python3.10/socket.py", line 833, in create_connection
    sock.connect(sa)
ConnectionRefusedError: [Errno 111] Connection refused

During handling of the above exception, another exception occurred:

Traceback (most recent call last):
  File "apps/frappe/frappe/utils/scheduler.py", line 75, in enqueue_events_for_site
    if is_scheduler_inactive():
  File "apps/frappe/frappe/utils/scheduler.py", line 114, in is_scheduler_inactive
    if is_scheduler_disabled(verbose=verbose):
  File "apps/frappe/frappe/utils/scheduler.py", line 127, in is_scheduler_disabled
    frappe.db.get_single_value("System Settings", "enable_scheduler")
  File "apps/frappe/frappe/database/database.py", line 786, in get_single_value
    ).run()
  File "apps/frappe/frappe/query_builder/utils.py", line 87, in execute_query
    result = frappe.db.sql(query, params, *args, **kwargs)  # nosemgrep
  File "apps/frappe/frappe/database/database.py", line 201, in sql
    self.connect()
  File "apps/frappe/frappe/database/database.py", line 115, in connect
    self._conn = self.get_connection()
  File "apps/frappe/frappe/database/mariadb/database.py", line 98, in get_connection
    conn = self._get_connection()
  File "apps/frappe/frappe/database/mariadb/database.py", line 104, in _get_connection
    return self.create_connection()
  File "apps/frappe/frappe/database/mariadb/database.py", line 107, in create_connection
    return pymysql.connect(**self.get_connection_settings())
  File "env/lib/python3.10/site-packages/pymysql/connections.py", line 352, in __init__
    self.connect()
  File "env/lib/python3.10/site-packages/pymysql/connections.py", line 668, in connect
    raise exc
pymysql.err.OperationalError: (2003, "Can't connect to MySQL server on '127.0.0.1' ([Errno 111] Connection refused)")

2024-01-29 09:53:32,136 ERROR scheduler Skipped queueing frappe.email.doctype.newsletter.newsletter.send_scheduled_email because it was found in queue for erp.gabby.com
2024-01-29 12:03:52,439 ERROR scheduler Skipped queueing frappe.desk.form.document_follow.send_hourly_updates because it was found in queue for erp.gabby.com
2024-01-29 14:40:04,671 ERROR scheduler Skipped queueing frappe.monitor.flush because it was found in queue for erp.gabby.com
2024-01-29 15:09:22,685 ERROR scheduler Skipped queueing frappe.utils.global_search.sync_global_search because it was found in queue for erp.gabby.com
2024-02-01 12:02:30,804 ERROR scheduler Skipped queueing erpnext.crm.doctype.social_media_post.social_media_post.process_scheduled_social_media_posts because it was found in queue for erp.gabby.com
2024-02-01 15:19:27,097 ERROR scheduler Exception in Enqueue Events for Site erp.gabby.com
Traceback (most recent call last):
  File "env/lib/python3.10/site-packages/pymysql/connections.py", line 736, in _read_bytes
    data = self._rfile.read(num_bytes)
  File "/usr/lib/python3.10/socket.py", line 705, in readinto
    return self._sock.recv_into(b)
ConnectionResetError: [Errno 104] Connection reset by peer

During handling of the above exception, another exception occurred:

Traceback (most recent call last):
  File "apps/frappe/frappe/utils/scheduler.py", line 75, in enqueue_events_for_site
    if is_scheduler_inactive():
  File "apps/frappe/frappe/utils/scheduler.py", line 114, in is_scheduler_inactive
    if is_scheduler_disabled(verbose=verbose):
  File "apps/frappe/frappe/utils/scheduler.py", line 127, in is_scheduler_disabled
    frappe.db.get_single_value("System Settings", "enable_scheduler")
  File "apps/frappe/frappe/database/database.py", line 786, in get_single_value
    ).run()
  File "apps/frappe/frappe/query_builder/utils.py", line 87, in execute_query
    result = frappe.db.sql(query, params, *args, **kwargs)  # nosemgrep
  File "apps/frappe/frappe/database/database.py", line 201, in sql
    self.connect()
  File "apps/frappe/frappe/database/database.py", line 115, in connect
    self._conn = self.get_connection()
  File "apps/frappe/frappe/database/mariadb/database.py", line 98, in get_connection
    conn = self._get_connection()
  File "apps/frappe/frappe/database/mariadb/database.py", line 104, in _get_connection
    return self.create_connection()
  File "apps/frappe/frappe/database/mariadb/database.py", line 107, in create_connection
    return pymysql.connect(**self.get_connection_settings())
  File "env/lib/python3.10/site-packages/pymysql/connections.py", line 352, in __init__
    self.connect()
  File "env/lib/python3.10/site-packages/pymysql/connections.py", line 636, in connect
    self._request_authentication()
  File "env/lib/python3.10/site-packages/pymysql/connections.py", line 911, in _request_authentication
    auth_packet = self._read_packet()
  File "env/lib/python3.10/site-packages/pymysql/connections.py", line 696, in _read_packet
    packet_header = self._read_bytes(4)
  File "env/lib/python3.10/site-packages/pymysql/connections.py", line 742, in _read_bytes
    raise err.OperationalError(
pymysql.err.OperationalError: (2013, 'Lost connection to MySQL server during query ([Errno 104] Connection reset by peer)')

2024-02-13 15:37:29,978 ERROR scheduler Exception in Enqueue Events for Site erp.gabby.com
Traceback (most recent call last):
  File "env/lib/python3.10/site-packages/pymysql/connections.py", line 616, in connect
    sock = socket.create_connection(
  File "/usr/lib/python3.10/socket.py", line 845, in create_connection
    raise err
  File "/usr/lib/python3.10/socket.py", line 833, in create_connection
    sock.connect(sa)
ConnectionResetError: [Errno 104] Connection reset by peer

During handling of the above exception, another exception occurred:

Traceback (most recent call last):
  File "apps/frappe/frappe/utils/scheduler.py", line 75, in enqueue_events_for_site
    if is_scheduler_inactive():
  File "apps/frappe/frappe/utils/scheduler.py", line 114, in is_scheduler_inactive
    if is_scheduler_disabled(verbose=verbose):
  File "apps/frappe/frappe/utils/scheduler.py", line 127, in is_scheduler_disabled
    frappe.db.get_single_value("System Settings", "enable_scheduler")
  File "apps/frappe/frappe/database/database.py", line 786, in get_single_value
    ).run()
  File "apps/frappe/frappe/query_builder/utils.py", line 87, in execute_query
    result = frappe.db.sql(query, params, *args, **kwargs)  # nosemgrep
  File "apps/frappe/frappe/database/database.py", line 201, in sql
    self.connect()
  File "apps/frappe/frappe/database/database.py", line 115, in connect
    self._conn = self.get_connection()
  File "apps/frappe/frappe/database/mariadb/database.py", line 98, in get_connection
    conn = self._get_connection()
  File "apps/frappe/frappe/database/mariadb/database.py", line 104, in _get_connection
    return self.create_connection()
  File "apps/frappe/frappe/database/mariadb/database.py", line 107, in create_connection
    return pymysql.connect(**self.get_connection_settings())
  File "env/lib/python3.10/site-packages/pymysql/connections.py", line 352, in __init__
    self.connect()
  File "env/lib/python3.10/site-packages/pymysql/connections.py", line 668, in connect
    raise exc
pymysql.err.OperationalError: (2003, "Can't connect to MySQL server on '127.0.0.1' ([Errno 104] Connection reset by peer)")

2024-02-13 18:14:00,682 ERROR scheduler Exception in Enqueue Events for Site erp.gabby.com
Traceback (most recent call last):
  File "env/lib/python3.10/site-packages/pymysql/connections.py", line 616, in connect
    sock = socket.create_connection(
  File "/usr/lib/python3.10/socket.py", line 845, in create_connection
    raise err
  File "/usr/lib/python3.10/socket.py", line 833, in create_connection
    sock.connect(sa)
ConnectionResetError: [Errno 104] Connection reset by peer

During handling of the above exception, another exception occurred:

Traceback (most recent call last):
  File "apps/frappe/frappe/utils/scheduler.py", line 75, in enqueue_events_for_site
    if is_scheduler_inactive():
  File "apps/frappe/frappe/utils/scheduler.py", line 114, in is_scheduler_inactive
    if is_scheduler_disabled(verbose=verbose):
  File "apps/frappe/frappe/utils/scheduler.py", line 127, in is_scheduler_disabled
    frappe.db.get_single_value("System Settings", "enable_scheduler")
  File "apps/frappe/frappe/database/database.py", line 786, in get_single_value
    ).run()
  File "apps/frappe/frappe/query_builder/utils.py", line 87, in execute_query
    result = frappe.db.sql(query, params, *args, **kwargs)  # nosemgrep
  File "apps/frappe/frappe/database/database.py", line 201, in sql
    self.connect()
  File "apps/frappe/frappe/database/database.py", line 115, in connect
    self._conn = self.get_connection()
  File "apps/frappe/frappe/database/mariadb/database.py", line 98, in get_connection
    conn = self._get_connection()
  File "apps/frappe/frappe/database/mariadb/database.py", line 104, in _get_connection
    return self.create_connection()
  File "apps/frappe/frappe/database/mariadb/database.py", line 107, in create_connection
    return pymysql.connect(**self.get_connection_settings())
  File "env/lib/python3.10/site-packages/pymysql/connections.py", line 352, in __init__
    self.connect()
  File "env/lib/python3.10/site-packages/pymysql/connections.py", line 668, in connect
    raise exc
pymysql.err.OperationalError: (2003, "Can't connect to MySQL server on '127.0.0.1' ([Errno 104] Connection reset by peer)")

