2023-12-21 10:16:36,454 ERROR frappe Could not take error snapshot: characters_written
Site: erp.gabby.com
Form Dict: {'args': '{"language":"English","country":"Nigeria","timezone":"Africa/Lagos","currency":"NGN","enable_telemetry":1,"full_name":"Gabriel Akinshola","email":"gabrielakinshola3@gmail.com","password":"gabriel","company_name":"Graceco","company_abbr":"G","chart_of_accounts":"Standard","fy_start_date":"2023-01-01","fy_end_date":"2023-12-31"}', 'cmd': 'frappe.desk.page.setup_wizard.setup_wizard.setup_complete'}
Traceback (most recent call last):
  File "/home/gabby/frappe-bench/apps/frappe/frappe/app.py", line 95, in application
    response = frappe.api.handle()
  File "/home/gabby/frappe-bench/apps/frappe/frappe/api.py", line 55, in handle
    return frappe.handler.handle()
  File "/home/gabby/frappe-bench/apps/frappe/frappe/handler.py", line 47, in handle
    data = execute_cmd(cmd)
  File "/home/gabby/frappe-bench/apps/frappe/frappe/handler.py", line 85, in execute_cmd
    return frappe.call(method, **frappe.form_dict)
  File "/home/gabby/frappe-bench/apps/frappe/frappe/__init__.py", line 1628, in call
    return fn(*args, **newargs)
  File "/home/gabby/frappe-bench/apps/frappe/frappe/desk/page/setup_wizard/setup_wizard.py", line 62, in setup_complete
    return process_setup_stages(stages, args)
  File "/home/gabby/frappe-bench/apps/frappe/frappe/desk/page/setup_wizard/setup_wizard.py", line 93, in process_setup_stages
    run_setup_success(user_input)
  File "/home/gabby/frappe-bench/apps/frappe/frappe/desk/page/setup_wizard/setup_wizard.py", line 121, in run_setup_success
    install_fixtures.install()
  File "/home/gabby/frappe-bench/apps/frappe/frappe/desk/page/setup_wizard/install_fixtures.py", line 16, in install
    sync_dashboards()
  File "/home/gabby/frappe-bench/apps/frappe/frappe/utils/dashboard.py", line 92, in sync_dashboards
    print(f"Updating Dashboard for {app_name}")
BrokenPipeError: [Errno 32] Broken pipe

During handling of the above exception, another exception occurred:

Traceback (most recent call last):
  File "/home/gabby/frappe-bench/apps/frappe/frappe/utils/error.py", line 60, in make_error_snapshot
    snapshot = get_snapshot(exception)
  File "/home/gabby/frappe-bench/apps/frappe/frappe/utils/error.py", line 155, in get_snapshot
    value = pydoc.text.repr(getattr(evalue, name))
AttributeError: characters_written
2024-01-18 14:16:07,468 ERROR frappe New Exception collected with id: 2024-01-18 14:14:49.920663-127.0.0.1-5dd
Site: erp.gabby.com
Form Dict: {}
2024-01-18 14:16:07,328 ERROR frappe New Exception collected with id: 2024-01-18 14:14:49.773893-127.0.0.1-8db
Site: erp.gabby.com
Form Dict: {}
2024-01-29 09:44:05,097 ERROR frappe New Exception collected with id: 2024-01-29 09:43:55.746516-127.0.0.1-32d
Site: erp.gabby.com
Form Dict: {}
2024-01-29 09:46:13,049 ERROR frappe New Exception collected with id: 2024-01-29 09:46:11.366064-127.0.0.1-c7f
Site: erp.gabby.com
Form Dict: {}
2024-02-21 11:48:32,711 ERROR frappe New Exception collected with id: 2024-02-21 11:48:24.892666-127.0.0.1-5c0
Site: erp.gabby.com
Form Dict: {'start': '2024-02-21', 'end': '2024-02-21'}
